<?xml version="1.0" encoding="utf-8"?>

<robot
  name="signaturebot">
  <link name="world"/>

  <link
    name="base_link">
    <inertial>
      <origin
        xyz="0.043934 0.06035 0.070386"
        rpy="0 0 0" />
      <mass
        value="0.35291" />
      <inertia
        ixx="0.0003254"
        ixy="3.9578E-07"
        ixz="2.8883E-06"
        iyy="0.0004041"
        iyz="1.6475E-07"
        izz="0.00040678" />
    </inertial>
    <visual>
      <origin
        xyz="0 0 0"
        rpy="0 0 0" />
      <geometry>
        <mesh
          filename="package://fyp/meshes/visual/base_link.STL" />
      </geometry>
      <material
        name="">
        <color
          rgba="0.75294 0.75294 0.75294 1" />
      </material>
    </visual>
    <collision name="base_collision">
      <origin
        xyz="0 0 0"
        rpy="0 0 0" />
      <geometry>
        <mesh
          filename="package://fyp/meshes/collision/base_link.STL" />
      </geometry>
    </collision>
  </link>

  <joint name="fixed" type="fixed">
    <parent link="world"/>
    <child link="base_link"/>
    <origin rpy="0 0 0" xyz="0 0 0"/>
  </joint>

  <link
    name="pitch_link">
    <inertial>
      <origin
        xyz="1.7832E-05 -0.0063839 0.00015736"
        rpy="0 0 0" />
      <mass
        value="0.034759" />
      <inertia
        ixx="2.9791E-06"
        ixy="0"
        ixz="0"
        iyy="5.3233E-06"
        iyz="0"
        izz="3.414E-06" />
    </inertial>
    <visual>
      <origin
        xyz="0 0 0"
        rpy="0 0 0" />
      <geometry>
        <mesh
          filename="package://fyp/meshes/visual/pitch_link.STL" />
      </geometry>
      <material
        name="">
        <color
          rgba="0.29804 0.29804 0.29804 1" />
      </material>
    </visual>
    <collision name="pitch_collision">
      <origin
        xyz="0 0 0"
        rpy="0 0 0" />
      <geometry>
        <mesh
          filename="package://fyp/meshes/collision/pitch_link.STL" />
      </geometry>
    </collision>
  </link>

  <joint
    name="pitch"
    type="revolute">
    <origin
      xyz="0.09680587 0.060004555 0.15025"
      rpy="-1.5708 0 1.5708" />
    <parent
      link="base_link" />
    <child
      link="pitch_link" />
    <axis
      xyz="0 0 1" />
    <limit
      lower="-1.5708"
      upper="0.8"
      effort="100"
      velocity="1.0" />
    <dynamics
      damping="0.5"
      friction="0.01" />
  </joint>

  <transmission name="tran1">
    <type>transmission_interface/SimpleTransmission</type>
    <joint name="pitch">
      <hardwareInterface>hardware_interface/EffortJointInterface</hardwareInterface>
    </joint>
    <actuator name="motor1">
      <hardwareInterface>EffortJointInterface</hardwareInterface>
      <!--mechanicalReduction>5</mechanicalReduction-->
      <mechanicalReduction>1</mechanicalReduction>
    </actuator>
  </transmission>

  <link
    name="yaw_link">
    <inertial>
      <origin
        xyz="-0.019758 -0.009982 0.087957"
        rpy="0 0 0" />
      <mass
        value="0.17499" />
      <inertia
        ixx="9.0705E-05"
        ixy="0"
        ixz="0"
        iyy="6.5527E-05"
        iyz="0"
        izz="0.00013037" />
    </inertial>
    <visual>
      <origin
        xyz="0 0 0"
        rpy="0 0 0" />
      <geometry>
        <mesh
          filename="package://fyp/meshes/visual/yaw_link.STL" />
      </geometry>
      <material
        name="">
        <color
          rgba="0.77647 0.75686 0.73725 1" />
      </material>
    </visual>
    <collision name="yaw_collision">
      <origin
        xyz="0 0 0"
        rpy="0 0 0" />
      <geometry>
        <mesh
          filename="package://fyp/meshes/collision/yaw_link.STL" />
      </geometry>
    </collision>
  </link>

  <joint
    name="yaw"
    type="revolute">
    <origin
      xyz="0 0.05008 0"
      rpy="1.5708 -1.5708 0" />
    <parent
      link="pitch_link" />
    <child
      link="yaw_link" />
    <axis
      xyz="0 0 1" />
    <limit
      lower="-1.3"
      upper="1.3"
      effort="100"
      velocity="1.0" />
    <dynamics
      damping="0.5"
      friction="0.01" />
  </joint>

  <transmission name="tran2">
    <type>transmission_interface/SimpleTransmission</type>
    <joint name="yaw">
      <hardwareInterface>hardware_interface/EffortJointInterface</hardwareInterface>
    </joint>
    <actuator name="motor2">
      <hardwareInterface>EffortJointInterface</hardwareInterface>
      <!--mechanicalReduction>10</mechanicalReduction-->
      <mechanicalReduction>1</mechanicalReduction>
    </actuator>
  </transmission>

  <link
    name="extension_link">
    <inertial>
      <origin
        xyz="-0.0037892 0.07262 -0.12942"
        rpy="0 0 0" />
      <mass
        value="0.13248" />
      <inertia
        ixx="0.00015884"
        ixy="0"
        ixz="0"
        iyy="0.00012513"
        iyz="2.127E-05"
        izz="4.3022E-05" />
    </inertial>
    <visual>
      <origin
        xyz="0 0 0"
        rpy="0 0 0" />
      <geometry>
        <mesh
          filename="package://fyp/meshes/visual/extension_link.STL" />
      </geometry>
      <material
        name="">
        <color
          rgba="0.49804 0.49804 0.49804 1" />
      </material>
    </visual>
    <collision name="extension_collision">
      <origin
        xyz="0 0 0"
        rpy="0 0 0" />
      <geometry>
        <mesh
          filename="package://fyp/meshes/collision/extension_link.STL" />
      </geometry>
    </collision>
  </link>

  <joint
    name="extension"
    type="prismatic">
    <origin
      xyz="0 -0.13608 0"
      rpy="1.5708 0 0" />
    <parent
      link="yaw_link" />
    <child
      link="extension_link" />
    <axis
      xyz="0 0 1" />
    <limit
      lower="0.0"
      upper="0.096"
      effort="100"
      velocity="0.5" />
    <dynamics
      damping="145.0"
      friction="5.5" />
    <!--dynamics
      damping="10.0"
      friction="1.0" /-->
  </joint>

  <transmission name="tran3">
    <type>transmission_interface/SimpleTransmission</type>
    <joint name="extension">
      <hardwareInterface>hardware_interface/EffortJointInterface</hardwareInterface>
    </joint>
    <actuator name="motor3">
      <hardwareInterface>EffortJointInterface</hardwareInterface>
      <!--mechanicalReduction>0.03927</mechanicalReduction-->
      <mechanicalReduction>1</mechanicalReduction>
    </actuator>
  </transmission>

  <gazebo>
    <plugin name="gazebo_ros_control" filename='libgazebo_ros_control.so'>
      <robotNamespace>/signaturebot</robotNamespace>
      <robotSimType>gazebo_ros_control/DefaultRobotHWSim</robotSimType>
    </plugin>
  </gazebo>

  <!--turn on self collisions for gazebo to detect mechanical interference-->
  <gazebo reference="base_link">
    <self_collide>1</self_collide>
  </gazebo>

  <gazebo reference="pitch_link">
    <self_collide>1</self_collide>
  </gazebo>

  <gazebo reference="yaw_link">
    <self_collide>1</self_collide>
  </gazebo>

  <gazebo reference="extension_link">
    <self_collide>1</self_collide>
  </gazebo>

  <gazebo>
    <plugin name="ground_truth" filename="libgazebo_ros_p3d.so">
      <frameName>world</frameName>
      <bodyName>extension_link</bodyName>
      <topicName>odom</topicName>
      <updateRate>20.0</updateRate>
    </plugin>
  </gazebo>

  <!--gazebo plugin that publishes JointState messages for all joints, works in conjuctiong with robot_state_publisher to give 3D robot state-->
  <gazebo>
    <plugin name="joint_state_publisher" filename="libgazebo_ros_joint_state_publisher.so">
      <jointName>pitch, yaw, extension</jointName>
      <updateRate>100.0</updateRate>
    </plugin>
  </gazebo>

</robot>
