<?xml version="1.0" encoding="utf-8"?>

<robot
  name="signaturebot">
  <link name="world"/>

  <link
    name="base_link">
    <inertial>
      <origin
        xyz="-0.000350133501068065 -0.0360219064102298 0.0653000932339098"
        rpy="0 0 0" />
      <mass
        value="0.352395733896831" />
      <inertia
        ixx="0.000404087077788787"
        ixy="-3.95777299375808E-07"
        ixz="-1.64745868933418E-07"
        iyy="0.000325399468893167"
        iyz="2.88826526143997E-06"
        izz="0.00040677570479938" />
    </inertial>
    <visual>
      <origin
        xyz="0 0 0"
        rpy="0 0 0" />
      <geometry>
        <mesh
          filename="package://fyp/meshes/base_link.STL" />
      </geometry>
      <material
        name="">
        <color
          rgba="0.752941176470588 0.752941176470588 0.752941176470588 1" />
      </material>
    </visual>
  </link>

  <joint name="fixed" type="fixed">
    <parent link="world"/>
    <child link="base_link"/>
    <origin rpy="0 0 0" xyz="0 0 0"/>
  </joint>

  <link
    name="link_p_1">
    <inertial>
      <origin
        xyz="-1.19933643488029E-05 -0.000103538143994622 0.00845194310862343"
        rpy="0 0 0" />
      <mass
        value="0.0528284254587736" />
      <inertia
        ixx="3.77153899343092E-06"
        ixy="-2.33326435640482E-10"
        ixz="-8.69910097856418E-10"
        iyy="4.23620818124235E-06"
        iyz="2.52958709372501E-11"
        izz="6.30698364184596E-06" />
    </inertial>
    <visual>
      <origin
        xyz="0 0 0"
        rpy="0 0 0" />
      <geometry>
        <mesh
          filename="package://fyp/meshes/link_p_1.STL" />
      </geometry>
      <material
        name="">
        <color
          rgba="0.752941176470588 0.752941176470588 0.752941176470588 1" />
      </material>
    </visual>
    <!--collision>
      <origin
        xyz="0 0 0"
        rpy="0 0 0" />
      <geometry>
        <mesh
          filename="package://fyp/meshes/link_p_1.STL" />
      </geometry>
    </collision-->
  </link>

  <joint
    name="joint_p_1"
    type="revolute">
    <origin
      xyz="0 0.016806 0.14525"
      rpy="0 0 0" />
    <parent
      link="base_link" />
    <child
      link="link_p_1" />
    <axis
      xyz="0 1 0" />
    <limit
      lower="-1.57"
      upper="1.57"
      effort="100"
      velocity="0.3" />
    <dynamics
      damping="0.0"
      friction="0.0" />
  </joint>

  <transmission name="tran1">
    <type>transmission_interface/SimpleTransmission</type>
    <joint name="joint_p_1">
      <hardwareInterface>hardware_interface/EffortJointInterface</hardwareInterface>
    </joint>
    <actuator name="motor1">
      <hardwareInterface>hardware_interface/EffortJointInterface</hardwareInterface>
      <mechanicalReduction>1</mechanicalReduction>
    </actuator>
  </transmission>

  <link
    name="link_y_1">
    <inertial>
      <origin
        xyz="0.0104876825955588 -0.0230156882718096 0.020941823734644"
        rpy="0 0 0" />
      <mass
        value="0.151826725642152" />
      <inertia
        ixx="6.38614671740467E-05"
        ixy="8.06821895942205E-06"
        ixz="-8.01171088344698E-07"
        iyy="8.82740990599378E-05"
        iyz="6.22836986686432E-07"
        izz="0.000127222977341237" />
    </inertial>
    <visual>
      <origin
        xyz="0 0 0"
        rpy="0 0 0" />
      <geometry>
        <mesh
          filename="package://fyp/meshes/link_y_1.STL" />
      </geometry>
      <material
        name="">
        <color
          rgba="0.752941176470588 0.752941176470588 0.752941176470588 1" />
      </material>
    </visual>
  </link>

  <joint
    name="joint_y_1"
    type="revolute">
    <origin
      xyz="0 0 0.02"
      rpy="0 0 0" />
    <parent
      link="link_p_1" />
    <child
      link="link_y_1" />
    <axis
      xyz="0 0 1" />
    <limit
      lower="-1.57"
      upper="1.57"
      effort="100"
      velocity="0.3" />
  </joint>

  <transmission name="tran2">
    <type>transmission_interface/SimpleTransmission</type>
    <joint name="joint_y_1">
      <hardwareInterface>hardware_interface/EffortJointInterface</hardwareInterface>
    </joint>
    <actuator name="motor2">
      <hardwareInterface>hardware_interface/EffortJointInterface</hardwareInterface>
      <mechanicalReduction>1</mechanicalReduction>
    </actuator>
  </transmission>

  <link
    name="link_s_1">
    <inertial>
      <origin
        xyz="-0.130540936042835 -0.00352627999201047 0.0734261633534493"
        rpy="0 0 0" />
      <mass
        value="0.14210555185115" />
      <inertia
        ixx="4.39802170061191E-05"
        ixy="4.6698112486318E-08"
        ixz="2.12695051978603E-05"
        iyy="0.000160918815683062"
        iyz="-6.50095590362535E-08"
        izz="0.000127755329199534" />
    </inertial>
    <visual>
      <origin
        xyz="0 0 0"
        rpy="0 0 0" />
      <geometry>
        <mesh
          filename="package://fyp/meshes/link_s_1.STL" />
      </geometry>
      <material
        name="">
        <color
          rgba="0.752941176470588 0.752941176470588 0.752941176470588 1" />
      </material>
    </visual>
  </link>

  <joint
    name="joint_s_1"
    type="prismatic">
    <origin
      xyz="0.16609 4E-05 -0.070079"
      rpy="0 0 0" />
    <parent
      link="link_y_1" />
    <child
      link="link_s_1" />
    <axis
      xyz="1 0 0" />
    <limit
      lower="0"
      upper="0.06"
      effort="100"
      velocity="0.05" />
  </joint>

  <transmission name="tran3">
    <type>transmission_interface/SimpleTransmission</type>
    <joint name="joint_s_1">
      <hardwareInterface>hardware_interface/EffortJointInterface</hardwareInterface>
    </joint>
    <actuator name="motor3">
      <hardwareInterface>hardware_interface/EffortJointInterface</hardwareInterface>
      <mechanicalReduction>1</mechanicalReduction>
    </actuator>
  </transmission>

  <gazebo>
    <plugin name="control" filename='libgazebo_ros_control.so'>
      <robotNamespace>/signaturebot</robotNamespace>
    </plugin>
  </gazebo>

  <!--gazebo plugin that publishes JointState messages for all joints, works in conjuctiong with robot_state_publisher to give 3D robot state-->
  <gazebo>
    <plugin name="joint_state_publisher" filename="libgazebo_ros_joint_state_publisher.so">
      <jointName>joint_p_1, joint_y_1, joint_s_1</jointName>
      <robotNamespace>/signaturebot</robotNamespace>
      <updateRate>100.0</updateRate>
    </plugin>
  </gazebo>

</robot>
